Workbook

Sheet Parin
A1: Site Detail
A3: Sr No | B3: Site Code | C3: Cluster | D3: Site Address | E3: Country | F3: State | G3: Region | H3: Type of Site | I3: Climatic Zone | J3: Sector | K3: Entity Owner | L3: Percentage
A4: 1 | B4: Parin | C4: India | D4: M/s Bagmane Developers Pvt. Ltd. CV raman nagar, Bangalore - 560093 | E4: India | F4: Karnataka | G4: South | H4: Multi Tenant | I4: Moderate | J4: Office | K4: BDPL | L4: 1
A8: Building Name | B8: Building Type | C8: Green Certification | D8: Total Construction Area | E8: Total Saleable Area | F8: Total Landscaping Area | G8: Facade Area | H8: Building Construction Start Date | I8: Building Completion Date | J8: Building Handover Start Date | K8: Building Handover End Date
A9: Parin | B9: REIT | C9: LEED-Platinum | D9: 44520.716 Sq. mtrs. | E9: 44520.716 Sq. mtrs. | F9: 6500 sq.ft | G9: 112003 sq.ft | H9: 2006 | I9: 2007 | J9: 2007 | K9: 2007
D10: 479216.99 sft | E10: 479216.99 sft | F10: 6500 sq.ft | G10: 112003 sq.ft
H12: 479217
A13: Floor Area Details
A14: Building Name | B14: Status | C14: Floor | D14: Floor Area (in sqft) | E14: Unit | G14: As per Fire NOC
A15: Parin | B15: Leased | C15: Ground Floor | D15: 33187.5 | G15: 1,491.17 Sq. mtrs. | H15: =CONVERT(H12,"ft^2","m^2") -> 44520.716
A16: Parin | B16: Leased | C16: 1st floor | D16: 30392.44 | G16: 448.31 Sq. mtrs. | H16: 44520.716
A17: Parin | B17: Leased | C17: 2nd floor | D17: 32199.27 | G17: 1,432.29 Sq. mtrs.
A18: Parin | B18: Leased | C18: 3rd floor | D18: 32199.27 | G18: 1,362.50 Sq. mtrs.
A19: Parin | B19: Leased | C19: 4th floor | D19: 32199.27 | G19: 62.05 Sq. mtrs.
A20: Parin | B20: Leased | C20: 5th floor | D20: 32199.27 | G20: 12,319.56 Sq. Mtrs.
A21: Parin | B21: Leased | C21: 6th floor | D21: 32199.27 | G21: 10,040.18 Sq. Mtrs.
A22: Parin | B22: Leased | C22: 7th floor | D22: 32199.27 | G22: 11,379.50 Sq. Mtrs.
A23: Parin | B23: Leased | C23: 8th floor | D23: 32199.27 | G23: 12,168.35 Sq. Mtrs.
A24: Parin | B24: Leased | C24: Terrace | D24: 31628.46 | G24: 2,092.55 Sq. Mtrs.
A26: Site Operational Details
A27: Type of connection | B27: No Of HT Meters | C27: No Of LT Meters (KWH) | D27: No Of Ammeters | E27: No Of Voltmeters | F27: Type Of Tarrif | G27: Service Provider | H27: Connected Load (KVA) | I27: Sanction Load(KVA) | J27: Contract Demand (KVA) | K27: Maximum Demand (KVA) | L27: Billing Demand (KVA) | M27: STP-Methodology | N27: STP Capacity (KLD)
A28: HT - Parin A Block | B28: 2 | C28: 52 | D28: 26 | E28: 14 | F28: 1 HT2B | G28: BESCOM | H28: 2400 | I28: 2400 | J28: 2400 | K28: 539 | L28: 2160 | M28: MBR | N28: 200
A29: HT - Parin B Block | B29: 7 | F29: 1 HT2B | G29: BESCOM | H29: 7499 | I29: 7499 | J29: 7499 | K29: 5108 | L29: 6749
A31: Air-condition Details
A32: Type of Air-condition | B32: Total HVAC Load (in TR)
A34: Air Cooled Chiller (2 Nos.)(A block) | B34: 640
A37: Water Source Details
A38: Type of Water Source | B38: Water Input (in KLD)
A39: Tanker | B39: 1472.46
A40: Borewell | B40: 255.3
A41: STP | B41: 2345.9
A43: Water Tank Details
A44: Type of Water Tank | B44: Location of Tank | C44: Tank Capacity(in KL) | D44: Size of Tank(in cu.ft.)
A45: Fire Water tank-1 (A block) | B45: Ground | C45: 260 | D45: =C45*35.3146 -> 9181.796
A46: Fire Water tank-2 (B block) | B46: Ground | C46: 260 | D46: =C46*35.3146 -> 9181.796
A47: Raw Water tank-1 (A block) | B47: Ground | C47: 50 | D47: =C47*35.3146 -> 1765.73
A48: Raw Water tank-2 (B block) | B48: Ground | C48: 50 | D48: =C48*35.3146 -> 1765.73
A49: Treated Water tank-1 (A block) | B49: Ground | C49: 50 | D49: =C49*35.3146 -> 1765.73
A50: Treated Water tank-2 (B block) | B50: Ground | C50: 50 | D50: =C50*35.3146 -> 1765.73
A51: Fire Water tank-1 | B51: Terrace | C51: 50 | D51: =C51*35.3146 -> 1765.73
...

Sheet Laurel
A1: Site Detail
A3: Sr No | B3: Site Code | C3: Cluster | D3: Site Address | E3: Country | F3: State | G3: Region | H3: Type of Site | I3: Climatic Zone | J3: Sector | K3: Entity Owner | L3: Percentage
A4: 1 | B4: Laurel | C4: India | D4: M/s Bagmane Developers Pvt. Ltd. Bagmane Tech Park, CV Ramana Nagar Bangalore-560093 | E4: India | F4: Karnataka | G4: East | H4: Multi-Tenant | I4: Moderate | J4: Office | K4: Bagmane Developers Pvt. Ltd. | L4: 1
A8: Building Name | B8: Building Type | C8: Green Certification | D8: Total Construction Area | E8: Total Saleable Area | F8: Total Landscaping Area | G8: Facade Area | H8: Building Construction Start Date | I8: Building Completion Date | J8: Building Handover Start Date | K8: Building Handover End Date
A9: LAUREL | B9: REIT | D9: 70029.64 Sq. mtrs. | E9: 71943.02 Sq. mtrs. | F9: 24000 sq.ft | G9: 99897 sq.ft | H9: 2005 | I9: 2008 | J9: 2008
D10: 753792.77 sft. | E10: 774388.22 sft.
A13: Floor Area Details
A14: Building Name | B14: Status | C14: Floor | D14: Floor Area (in sqft) | E14: Unit | G14: As per Fire NOC
A15: Utility Block | B15: Leased | C15: Ground Floor
A16: Utility Block | B16: Leased | C16: 1st floor
A17: Utility Block | B17: Leased | C17: 2nd floor
A18: Utility Block | B18: Leased | C18: 3rd floor
A19: Utility Block | B19: Leased | C19: Terrace | G19: 16602.12 Sq.Mt
A20: Office Block | B20: Leased | C20: Ground floor | G20: 13328.96 Sq.Mt
A21: Office Block - A Block | B21: Leased | C21: 1st floor | D21: 22052 | G21: 8407 Sq.Mtr
A22: Office Block- A Block | B22: Leased | C22: 2nd floor | D22: 22035 | G22: 7779 Sq.Mtr
A23: Office Block- A Block | B23: Leased | C23: 3rd floor | D23: 23496 | G23: 8202.31 Sq.Mtr
A24: Office Block- A Block | B24: Leased | C24: 4th floor | D24: 23496 | G24: 8193.44 Sq.Mtr
A25: Office Block- A Block | B25: Leased | C25: 5th floor | D25: 23496 | G25: 8193.44 Sq.Mtr
A26: Office Block- A Block | B26: Leased | C26: 6th floor | D26: 23495 | G26: 8193.44 Sq.Mtr
A27: Office Block- A Block | B27: Leased | C27: 7th floor | D27: 26326 | G27: 7720 Sq.Mtr
A28: Office Block- A Block | B28: Leased | C28: 8th floor | D28: 22922 | G28: 7720 Sq.Mtr
A29: Office Block - B Block | B29: Leased | C29: 1st floor | D29: 23593
A30: Office Block- B Block | B30: Leased | C30: 2nd floor | D30: 18136
A31: Office Block- B Block | B31: Leased | C31: 3rd floor | D31: 26172
A32: Office Block- B Block | B32: Leased | C32: 4th floor | D32: 26172
A33: Office Block- B Block | B33: Leased | C33: 5th floor | D33: 26172
A34: Office Block- B Block | B34: Leased | C34: 6th floor | D34: 26172
A35: Office Block- B Block | B35: Leased | C35: 7th floor | D35: 18333
A36: Office Block- B Block | B36: Leased | C36: 8th floor | D36: 26091
A37: Office Block - C Block | B37: Leased | C37: 1st floor | D37: 26091
A38: Office Block - C Block | B38: Leased | C38: 2nd floor | D38: 26091
A39: Office Block - C Block | B39: Leased | C39: 3rd floor | D39: 26172
A40: Office Block - C Block | B40: Leased | C40: 4th floor | D40: 26172
... A52: Office Block - D Block | B52: Leased | C52: 8th floor | D52: 23533
A58: Site Operational Details
A59: Type of connection | B59: No Of HT Meters | C59: No Of LT Meters (KWH) | D59: No Of Ammeters | E59: No Of Voltmeters | F59: Type Of Tarrif | G59: Service Provider | H59: Connected Load (KVA) | I59: Sanction Load(KVA) | J59: Contract Demand (KVA) | K59: Maximum Demand (KVA) | L59: Billing Demand (KVA) | M59: STP-Methodology | N59: STP Capacity (KLD)
A60: HT - Office Block | B60: 2 | C60: 170 | D60: 83 | E60: 47 | F60: Commercial-HT2B1 | G60: BESCOM | H60: 7938 | I60: 9000 | J60: 9000 | K60: 5000 | L60: 8100 | M60: MBR | N60: 330
A62: Air-condition Details
A63: Type of Air-condition | B63: Total HVAC Load (in TR)
...

Sheet Laurel 1
F4: Area (Sft) | I4: Parking Details
B5: Building Name | C5: Block | D5: Client Name | E5: Floor | F5: Carpet Area(in sqft) | G5: Leased Area(in sqft) | H5: Super Built-up Area (in sqft) | I5: Parking Floor | J5: No. of parkings as per Plan | K5: No. of parkings as on Actuals | L5: No. of Stack Parking | M5: No. of Open Parking | N5: No. of Covered Parking | O5: No. of Visitors Parking | P5: No. of Reserved Parking | Q5: No. of 2W Parking | R5: No. of 4W Parking
B6: Laurel | C6: A | D6: Mphasis | E6: 1st
B7: Laurel | C7: A | D7: Opentext | E7: 2nd
B8: Laurel | C8: A | D8: Opentext | E8: 3rd
B9: Laurel | C9: A | D9: Volvo Group-India | E9: 4th
B10: Laurel | C10: A | D10: Opentext | E10: 5th
B11: Laurel | C11: A | D11: Volvo Group-India | E11: 6th
B12: Laurel | C12: A | D12: Infineon | E12: 7th
B13: Laurel | C13: A | D13: Opentext | E13: 8th
B14: Laurel | C14: B | D14: SIMA | E14: 1st
B15: Laurel | C15: B | D15: Volvo | E15: 1st
B16: Laurel | C16: B | D16: ROHM | E16: 1st
B17: Laurel | C17: B | D17: Mitsogo | E17: 1st
... B42: Laurel | C42: D | D42: Opentext | E42: 8th

Sheet Tridib
A1: Site Detail
A3: Sr No | B3: Site Code | C3: Cluster | D3: Site Address | E3: Country | F3: State | G3: Region | H3: Type of Site | I3: Climatic Zone | J3: Sector | K3: Entity Owner | L3: Percentage
A4: 1 | B4: Tridib | C4: India | D4: M/s Bagmane Developers Pvt. Ltd. Bagmane Tech Park, CV Raman Nagar-560093 | E4: India | F4: Karnataka | G4: East | H4: Multi-Tenant | I4: Moderate | J4: Office | K4: Bagmane Developers Pvt Ltd | L4: 1
A8: Building Name | B8: Building Type | C8: Green Certification | D8: Total Construction Area | E8: Total Saleable Area | F8: Total Landscaping Area | G8: Facade Area | H8: Building Construction Start Date | I8: Building Completion Date | J8: Building Handover Start Date | K8: Building Handover End Date
A9: Tridib | B9: REIT | C9: NA | D9: 63652.40 Sq. mtrs. | E9: 567991 Sq. ft. | F9: 14414.31 sq.ft | G9: 177636 sq.ft | H9: 2006 | I9: 2009 | J9: 2009 | K9: 2009
D10: 685148.73
D11: sft
A13: Floor Area Details
A14: Building Name | B14: Status | C14: Floor | D14: Floor Area (in sqft) | E14: Unit | G14: As per Fire NOC
A15: Office Block | B15: Leased | C15: Ground floor-A Block | D15: 33431 | G15: 6320 Sq. Mtrs.
A16: Office Block | B16: Leased | C16: 1st floor-A Block | D16: 33019 | G16: 5931 Sq. Mtrs.
A17: Office Block | B17: Leased | C17: 2nd floor-A Block | D17: 37149 | G17: 5931 Sq. Mtrs.
A18: Office Block | B18: Leased | C18: 3rd floor-A Block | D18: 36049 | G18: 5931 Sq. Mtrs.
A19: Office Block | B19: Leased | C19: 4th floor-A Block | D19: 36058 | G19: 6074 Sq. Mtrs.
A20: Office Block | B20: Leased | C20: 5th floor-A Block | D20: 36014 | G20: 5931 Sq. Mtrs.
A21: Office Block | B21: Leased | C21: 6th floor-A Block | D21: 36688 | G21: 6074 Sq. Mtrs.
A22: Office Block | B22: Leased | C22: 7th floor-A Block | D22: 35874 | G22: 6074 Sq. Mtrs.
A23: Office Block | B23: Leased | C23: Ground floor-B Block | D23: 33431 | G23: 5931 Sq. Mtrs.
A24: Office Block | B24: Leased | C24: 1st floor-B Block | D24: 33295
A25: Office Block | B25: Leased | C25: 2nd floor-B Block | D25: 36055
A26: Office Block | B26: Leased | C26: 3rd floor-B Block | D26: 36314
A27: Office Block | B27: Leased | C27: 4th floor-B Block | D27: 36055
A28: Office Block | B28: Leased | C28: 5th floor-B Block | D28: 35874
A29: Office Block | B29: Leased | C29: 6th floor-B Block | D29: 36281
A30: Office Block | B30: Leased | C30: 7th floor-B Block | D30: 36281
A31: Common | B31: Leased | C31: Upper Basement-parking | D31: 60435 | G31: 9592 Sq.Mtrs
A32: Common | B32: Leased | C32: Lower Baement-parking | D32: 92906
A33: Common | B33: Leased | C33: Terrace-café | D33: 61844
A35: Site Operational Details
A36: Type of connection | B36: No Of HT Meters | C36: No Of LT Meters (KWH) | D36: No Of Ammeters | E36: No Of Voltmeters | F36: Type Of Tarrif | G36: Service Provider | H36: Connected Load (KVA) | I36: Sanction Load(KVA) | J36: Contract Demand (KVA) | K36: Maximum Demand (KVA) | L36: Billing Demand (KVA) | M36: STP-Methodology | N36: STP Capacity (KLD)
A37: HT - Office Block | B37: 1 | C37: 145 | D37: 22 | E37: 11 | F37: Commercial-HT2B1 | G37: BESCOM | H37: 6500 | I37: 6500 | J37: 6500 | K37: 3000 | L37: 5850 | M37: ASP | N37: 200 KLD
A39: Air-condition Details
A40: Type of Air-condition | B40: Total HVAC Load (in TR)
A41: Water Cooled Chiller (2 Nos.) | B41: 0
A42: Air Cooled Chiller (3 Nos.) | B42: 1680
A45: Water Source Details-Per Day
A46: Type of Water Source | B46: Water Input (in KLD)
A47: Tanker | B47: 60
A48: Borewell | B48: 30
A49: STP | B49: 80
...

Sheet Crown
A1: Site Detail
A3: Sr No | B3: Site Code | C3: Cluster | D3: Site Address | E3: Country | F3: State | G3: Region | H3: Type of Site | I3: Climatic Zone | J3: Sector | K3: Entity Owner | L3: Percentage
A4: 1 | B4: BTP | C4: India | D4: M/s Bagmane Developers Pvt. Ltd. CV Raman nagara, Bangalore - 560093 | E4: India | F4: Karnataka | G4: East | H4: Singe Tenant | I4: Moderate | J4: Office | K4: Bagmane developers Private Limited (BRPL) | L4: 1
A8: Building Name | B8: Building Type | C8: Green Certification | D8: Total Construction Area | E8: Total Saleable Area | F8: Total Landscaping Area (SFT) | G8: Facade Area (SFT) | H8: Building Construction Start Date | I8: Building Completion Date | J8: Building Handover Start Date | K8: Building Handover End Date
A9: Crown | B9: REIT | C9: LEED | D9: 290709.13 | E9: 290709.13 | F9: 15096.28 | G9: 148706.21 | H9: 2004 | I9: 2006 | J9: 2007 | K9: 2007
A13: Floor Area Details
A14: Building Name | B14: Status | C14: Floor | D14: Floor Area (in sqft) | E14: Unit | G14: As per Fire NOC
A15: Lab Area | B15: Leased | C15: Ground Floor | D15: 25643.71 | E15: SFT | G15: 4338.10 Sq.mts
A16: Parking Area | B16: Leased | C16: 1st floor | D16: 7087.59 | E16: SFT | G16: 4447.67 Sq.mts
A17: Office Block & Café | B17: Leased | C17: 2nd floor | D17: 45969.67 | E17: SFT | G17: 3670.02 Sq. mtrs.
A18: Office Block | B18: Leased | C18: 3rd floor | D18: 35881.1 | E18: SFT | G18: 2821.00 Sq. mtrs.
A19: Office Block | B19: Leased | C19: 4th floor | D19: 35881.1 | E19: SFT | G19: 2821.00 Sq. mtrs.
A20: Office Block | B20: Leased | C20: 5th floor | D20: 35881.1 | E20: SFT | G20: 2821.00 Sq. mtrs.
A21: Office Block & Refuge | B21: Leased | C21: 6th floor | D21: 32602.62 | E21: SFT | G21: 2821.00 Sq. mtrs.
A22: Office Block | B22: Leased | C22: 7th floor | D22: 35881.1 | E22: SFT | G22: 2821.00 Sq. mtrs.
A23: Office Block | B23: Leased | C23: 8th floor | D23: 35881.1 | E23: SFT | G23: 2821.00 Sq. mtrs.
A25: Site Operational Details
A26: Type of connection | B26: No Of HT Meters | C26: No Of LT Meters (KWH) | D26: No Of Ammeters | E26: No Of Voltmeters | F26: Type Of Tarrif | G26: Service Provider | H26: Connected Load (KVA) | I26: Sanction Load(KVA) | J26: Contract Demand (KVA) | K26: Maximum Demand (KVA) | L26: Billing Demand (KVA) | M26: STP-Methodology | N26: STP Capacity (KLD)
A27: HT - Utility Block | B27: 2 | C27: 47 | D27: 58 | E27: 12 | F27: Commercial-S7HT51 | G27: BESCOM | H27: 2690 | I27: 2690 | J27: 2690 | K27: 1178 | L27: 2421 | M27: MBR | N27: 150
A30: Air-condition Details
A31: Type of Air-condition | B31: Total HVAC Load (in TR)
A32: Water Cooled Chiller (1 Nos.) | B32: 375
A33: Air Cooled Chiller (1 Nos.) | B33: 250
A36: Water Source Details
A37: Type of Water Source | B37: Water Input (in KLD)
A38: Tanker | B38: 30
A39: Borewell | B39: 50
A40: STP | B40: 150
A42: Water Tank Details
A43: Type of Water Tank | B43: Location of Tank | C43: Tank Capacity(in KL) | D43: Size of Tank(in cu.ft.)
A44: Fire Water tank-1 | B44: Ground floor | C44: 200 | D44: =C44*35.3146 -> 7062.92
A45: Buffer tank | B45: Ground floor | C45: 50 | D45: =C45*35.3146 -> 1765.73
A46: Raw Water tank | B46: Ground floor | C46: 60 | D46: =C46*35.3146 -> 2118.876
A47: Treated Water tank | B47: Ground floor | C47: 60 | D47: =C47*35.3146 -> 2118.876
A48: Fire Water tank-1 | B48: Terrace | C48: 30 | D48: =C48*35.3146 -> 1059.438
A49: Domestic Treated Water tank - 1 | B49: Terrace | C49: 30 | D49: =C49*35.3146 -> 1059.438
A50: Domestic Treated Water tank - 2 | B50: Terrace | C50: 30 | D50: =C50*35.3146 -> 1059.438
A51: Domestic Treated Water tank - 3 | B51: Terrace | C51: 30 | D51: =C51*35.3146 -> 1059.438
A52: Flushing Tank - 1 | B52: Terrace | C52: 30 | D52: =C52*35.3146 -> 1059.438
A53: Flushing Tank - 2 | B53: Terrace | C53: 30 | D53: =C53*35.3146 -> 1059.438
...

Sheet Quay
A1: Site Detail
A3: Sr No | B3: Site Code | C3: Cluster | D3: Site Address | E3: Country | F3: State | G3: Region | H3: Type of Site | I3: Climatic Zone | J3: Sector | K3: Entity Owner | L3: Percentage
A4: 1 | B4: Quay | C4: India | D4: Bagmane Developers Pvt. Ltd. Laurel ’B’ Block, 5th Floor, Bagmane Tech Park, C V Raman Nagar, Bangalore – 560 093 | E4: India | F4: Karnataka | G4: South | H4: Multi Tenant | I4: Moderate | J4: Office | K4: Bagmane Quay Private Limited (BQPL) | L4: 1
A8: Building Name | B8: Building Type | C8: Green Certification | D8: Total Construction Area | E8: Total Saleable Area | F8: Total Landscaping Area | G8: Facade Area | H8: Building Construction Start Date | I8: Building Completion Date | J8: Building Handover Start Date | K8: Building Handover End Date
A9: Quay | B9: REIT | C9: LEED-Gold | D9: 850192.17 Sq. mtrs. | E9: 61263 Sq. mtrs. | F9: 15923.08 sq.ft | G9: 1050289 sq.ft | H9: 2018 | I9: 2020 | J9: 2020 | K9: 2021
D10: =10.764*850192.17 -> 9151468.5 | E10: =10.764*61263 -> 659434.93
A13: Floor Area Details
A14: Building Name | B14: Status | C14: Floor | D14: Floor Area (in sqft) | E14: Unit | G14: As per Fire NOC
A15: Quay | B15: Leased | C15: Ground floor | D15: 25350 | G15: 4254 Sq. Mtrs.
A16: Quay | B16: Leased | C16: 1st floor | D16: 45684 | G16: 4137 Sq. Mtrs.
A17: Quay | B17: Leased | C17: 2nd floor | D17: 74944 | G17: 5989 Sq. Mtrs.
A18: Quay | B18: Leased | C18: 3rd floor | D18: 74865 | G18: 5989 Sq. Mtrs.
A19: Quay | B19: Leased | C19: 4th floor | D19: 74923.55 | G19: 5989 Sq. Mtrs.
A20: Quay | B20: Leased | C20: 5th floor | D20: 69954.53 | G20: 5989 Sq. Mtrs.
A21: Quay | B21: Leased | C21: 6th floor | D21: 74659.97 | G21: 5989 Sq. Mtrs.
A22: Quay | B22: Leased | C22: 7th floor | D22: 74660 | G22: 5989 Sq. Mtrs.
A23: Quay | B23: Leased | C23: 8th floor | D23: 69296 | G23: 5989 Sq. Mtrs.
A24: Quay | B24: Leased | C24: 9th floor | D24: 74848 | G24: 5989 Sq. Mtrs.
A25: Quay | B25: Leased | C25: Terrace | D25: 12397.77 | G25: 1334 Sq. Mtrs.
A26: Quay | B26: Leased | C26: Basement-3 | D26: 78418.88 | G26: 7720 Sq. Mtrs.
... A28: Quay | B28: Leased | C28: Basement-1 | D28: 83659 | G28: 7630 Sq. Mtrs.
A30: Site Operational Details
A31: Type of connection | B31: No Of HT Meters | C31: No Of LT Meters (KWH) | D31: No Of Ammeters | E31: No Of Voltmeters | F31: Type Of Tarrif | G31: Service Provider | H31: Connected Load (KVA) | I31: Sanction Load(KVA) | J31: Contract Demand (KVA) | K31: Maximum Demand (KVA) | L31: Billing Demand (KVA) | M31: STP-Methodology | N31: STP Capacity (KLD)
A32: HT - Utility Block | B32: 2 | C32: 58 | D32: 27 | E32: 5 | F32: Commercial-HT2B | G32: BESCOM | H32: 5000 | I32: 5000 | J32: 5000 | K32: 2098 | L32: 4500 | M32: MBBR | N32: 350
A34: Air-condition Details
A35: Type of Air-condition | B35: Total HVAC Load (in TR)
A36: Water Cooled Chiller (2 Nos.) | B36: 700
A37: Air Cooled Chiller (1 Nos.) | B37: 350
A40: Water Source Details
A41: Type of Water Source | B41: Water Input (in KLD)
A42: Tanker | B42: 44
A43: Borewell | B43: 100
A44: STP | B44: 140
A46: Water Tank Details
A47: Type of Water Tank | B47: Location of Tank | C47: Tank Capacity(in KL) | D47: Size of Tank(in cu.ft.)
A48: Fire water tank - 1 | B48: Basement-1 | C48: 375 | D48: =C48*35.315 -> 13243.125
A49: Fire water tank - 2 | B49: Basement-1 | C49: 375 | D49: =C49*35.315 -> 13243.125
A50: Raw water tank | B50: Basement-1 | C50: 120 | D50: =C50*35.315 -> 4237.8
A51: Treated water tank | B51: Basement-1 | C51: 125 | D51: =C51*35.315 -> 4414.375
A52: Rain water tank | B52: Ground | C52: 130 | D52: =C52*35.315 -> 4590.95
...

Sheet Lakeview
A1: Site Detail
A3: Sr No | B3: Site Code | C3: Cluster | D3: Site Address | E3: Country | F3: State | G3: Region | H3: Type of Site | I3: Climatic Zone | J3: Sector | K3: Entity Owner | L3: Percentage
A4: 1 | B4: BTP | C4: India | D4: M/s Bagmane Developers Pvt. Ltd. Laurel 'B' Block,5th Floor,Bagmane Tech Park,C V Raman Nagar,Bangalore 560093 | E4: India | F4: Karnataka | G4: South | H4: Multi Tenant | I4: Moderate | J4: Office | K4: Bagmane Developers Private Limited (BDPL) | L4: 1
A8: Building Name | B8: Building Type | C8: Green Certification | D8: Total Construction Area | E8: Total Saleable Area | F8: Total Landscaping Area | G8: Facade Area | H8: Building Construction Start Date | I8: Building Completion Date | J8: Building Handover Start Date | K8: Building Handover End Date
A9: Lakeview | B9: REIT | C9: LEED-Platinum | D9: 53,242.85 Sq. mtrs. | E9: 50,454.57 Sq. mtrs. | F9: 24479 sq.ft | G9: 95638 sq.ft | H9: NA | I9: NA | J9: NA | K9: 2005
D10: =10.764*53242.85 -> 573106.04 | E10: =10.764*50454.57 -> 543092.99 | F10: 24479 | G10: 95638
A13: Floor Area Details | D13: Client | E13: A Block | G13: Client | H13: B Block
A14: Building Name | B14: Status | C14: Floor | E14: Floor Area (in sqft) | F14: Unit | H14: Floor Area (in sqft) | I14: Unit | J14: Floor Area (in sqft) | K14: Unit | M14: As per Fire NOC
A15: Utility Block | B15: Leased | C15: Ground Floor | J15: 67118.93 | L15: Ground Floor | M15: 6,235.55 Sq. mtrs.
A16: Office Block | B16: Leased | C16: 1st floor | D16: Alstom | J16: 59173.439 | L16: First Floor | M16: 5,497.39 Sq. mtrs.
A17: Office Block | B17: Leased | C17: 2nd floor | D17: UD Trucks | J17: 59173.439 | L17: Second Floor | M17: 5,497.39 Sq. mtrs.
A18: Office Block | B18: Leased | C18: 3rd floor | D18: SAP | J18: 60125.72 | L18: Third Floor | M18: 5,585.86 Sq. mtrs.
A19: Office Block | B19: Leased | C19: 4th floor | D19: Boeing | J19: 60125.72 | L19: Fourth Floor | M19: 5,585.86 Sq. mtrs.
A20: Office Block | B20: Leased | C20: 5th floor | D20: Texas Instruments | J20: 60125.72 | L20: Fifth Floor | M20: 5,585.86 Sq. mtrs.
A21: Office Block | B21: Leased | C21: 6th floor | D21: Boeing | J21: 56289.786 | L21: Sixth Floor | M21: 5,229.49 Sq. Mtrs.
A22: Office Block | B22: Leased | C22: 7th floor | D22: Texas Instruments | J22: 56289.786 | L22: Seventh Floor | M22: 5,229.49 Sq. Mtrs.
A23: Office Block | B23: Leased | C23: 8th floor | J23: 56289.786 | L23: Eighth Floor | M23: 5,229.49 Sq. Mtrs.
A24: MLCP | B24: Leased | C24: Ground Floor to 5th floor | J24: 94678.751 | K24: =J24/6 -> 15779.792 | M24: 8,795.94 Sq. Mtrs.
A26: Site Operational Details
A27: Type of connection | B27: No Of HT Meters | C27: No Of LT Meters (KWH) | D27: No Of Ammeters | E27: No Of Voltmeters | F27: Type Of Tarrif | G27: Service Provider | H27: Connected Load (KVA) | I27: Sanction Load(KVA) | J27: Contract Demand (KVA) | K27: Maximum Demand (KVA) | L27: Billing Demand (KVA) | M27: STP-Methodology | N27: STP Capacity (KLD)
A28: HT - Utility & Office Block | B28: 2 | C28: 97 | D28: 53 | E28: 52 | F28: Commercial-HT2b | G28: BESCOM | H28: 4300 | I28: 4300 | J28: 3870 | K28: 1758 | L28: 3870 | M28: ASP | N28: 250
A30: Air-condition Details
A31: Type of Air-condition | B31: Total HVAC Load (in TR) | I31: =L28/I28 -> 0.9
A32: Water Cooled Chiller | B32: NO
A33: Air Cooled Chiller (5 Nos.) | B33: 1500
A36: Water Source Details - Per month
A37: Type of Water Source | B37: Water Input (in KLD)
A38: Tanker | B38: 0
A39: Borewell | B39: 3434
A40: STP | B40: 2873
A42: Water Tank Details
A43: Type of Water Tank | B43: Location of Tank | C43: Tank Capacity(in KL) | D43: Size of Tank(in cu.ft.)
A44: Fire Sump | B44: A-Block Ground UG sump | C44: 250 | D44: =C44*35.3146 -> 8828.65
A45: Raw Sump | B45: A-Block Ground UG sump | C45: 80 | D45: =C45*35.3146 -> 2825.168
A46: Filter Sump | B46: A-Block Ground UG sump | C46: 80 | D46: =C46*35.3146 -> 2825.168
A47: Raw Sump | B47: B-Block Ground UG sump | C47: 80 | D47: =C47*35.3146 -> 2825.168
A48: Filter Sump | B48: B-Block Ground UG sump | C48: 80 | D48: =C48*35.3146 -> 2825.168
A49: Fire Tank | B49: A-Block Terrace | C49: 25 | D49: =C49*35.3146 -> 882.865
A50: Domestic Tank | B50: A-Block Terrace | C50: 32 | D50: =C50*35.3146 -> 1130.0672
A51: Gents Flush | B51: A-Block Terrace | C51: 12 | D51: =C51*35.3146 -> 423.7752
...

Sheet Lakeview Car Park Details
F1: Area (Sft) | J1: Parking Details
B2: Building Name | C2: Block | D2: Client Name | E2: Floor | F2: Carpet Area(in sqft) | G2: Leased Area(in sqft) | H2: Super Built-up Area (in sqft) | J2: Parking Floor | K2: No. of parkings as per Plan | L2: No. of parkings as on Actuals | M2: No. of Stack Parking | N2: No. of Open Parking | O2: No. of Covered Parking | P2: No. of Visitors Parking | Q2: No. of Reserved Parking | R2: No. of 2W Parking | S2: No. of 4W Parking
B3: Lakeview | C3: A | D3: - | E3: GF | J3: Ground Floor | K3: 200 | L3: 200 | M3: 0 | N3: 133 | O3: 67 | P3: 0 | Q3: 4 | R3: 0 | S3: 200
B4: Lakeview | C4: A | D4: Alstom | E4: 1st | G4: 38232 | H4: 38232 | J4: Ground Floor | K4: ='[1]Lakeview Summary'!C5+'[1]Lakeview Summary'!D5 -> 33 | L4: 33
B5: Lakeview | C5: A | D5: UD Trucks | E5: 2nd | G5: 42091 | H5: 42091
B6: Lakeview | C6: A | D6: SAP | E6: 3rd | G6: 42091 | H6: 42091
B7: Lakeview | C7: A | D7: Boeing | E7: 4th | G7: 42091 | H7: 42091
B8: Lakeview | C8: A | D8: Texas Instruments | E8: 5th | G8: 42091 | H8: 42091
B9: Lakeview | C9: A | D9: Boeing | E9: 6th | G9: 42465 | H9: 42465
B10: Lakeview | C10: A | D10: Texas Instruments | E10: 7th | G10: 42465 | H10: 42465
B11: Lakeview | C11: B | D11: Renesas | E11: GF | G11: 15015 | H11: 15015
B12: Lakeview | C12: B | D12: Texas Instruments | E12: 1st | G12: 27378 | H12: 27378
B13: Lakeview | C13: B | D13: Texas Instruments | E13: 2nd | G13: 32000 | H13: 32000
B14: Lakeview | C14: B | D14: Texas Instruments | E14: 3rd | G14: 32000 | H14: 32000
B15: Lakeview | C15: B | D15: Texas Instruments | E15: 4th | G15: 32000 | H15: 32000
B16: Lakeview | C16: B | D16: Texas Instruments | E16: 5th | G16: 32200 | H16: 32200
... B18: Lakeview | C18: B | D18: Texas Instruments | E18: 7th | G18: 31877 | H18: 31877
J20: MLCP Parking
I21: Client Name | J21: Parking Floor | K21: No. of parkings as per Plan | L21: No. of parkings as on Actuals | M21: No. of Stack Parking | N21: No. of Open Parking | O21: No. of Covered Parking | P21: No. of Visitors Parking | Q21: No. of Reserved Parking | R21: No. of 2W Parking | S21: No. of 4W Parking
I22: Texas Instruments, Boeing, Bagmane & Renesas | J22: Level 1 | K22: 72 | L22: 72 | M22: 0 | N22: 0 | O22: 72 | P22: 0 | Q22: 0 | R22: 0 | S22: 72
I23: Texas Instruments | J23: Level 2 | K23: 72 | L23: 72 | M23: 0 | N23: 0 | O23: 72 | P23: 0 | Q23: 0 | R23: 0 | S23: 72
I24: Texas Instruments | J24: Level 3 | K24: 72 | L24: 72 | M24: 0 | N24: 0 | O24: 72 | P24: 0 | Q24: 0 | R24: 0 | S24: 72
I25: Alstom& UD Trucks | J25: Level 4 | K25: 72 | L25: 72 | M25: 0 | N25: 0 | O25: 72 | P25: 0 | Q25: 0 | R25: 0 | S25: 72
I26: SAP Concur& Texas Instruments | J26: Level 5 | K26: 72 | L26: 72 | M26: 0 | N26: 0 | O26: 72 | P26: 0 | Q26: 0 | R26: 0 | S26: 72
I27: Boeing | J27: Level 6 | K27: 72 | L27: 72 | M27: 0 | N27: 0 | O27: 72 | P27: 0 | Q27: 0 | R27: 0 | S27: 72
I28: Texas Instruments | J28: Level 7 | K28: 72 | L28: 72 | M28: 0 | N28: 0 | O28: 72 | P28: 0 | Q28: 0 | R28: 0 | S28: 72
K47: Laurel ’B’ Block, 5th Floor, | L47: =CONCATENATE(K47,K48,K49) -> Laurel ’B’ Block, 5th Floor,Bagmane Tech Park, C V Raman Nagar,Bangalore – 560 093
K48: Bagmane Tech Park, C V Raman Nagar,
K49: Bangalore – 560 093 | L49: =16*18 -> 288
L50: =L49/40 -> 7.2
L51: =L50*103 -> 741.6 | M51: =140*18 -> 2520
M52: =60*18 -> 1080
M53: 742

Sheet Lakeview Car park Summary
B3: Lakeview Parking Summary
B4: Client | C4: GROUND FLOOR | D4: External | E4: MLCP | F4: MLCP Level details | G4: Total | H4: Actual allocation as per agreement
B5: Alstom | C5: 19 | D5: 14 | E5: 32 | F5: Level #3 - 32 | G5: =SUM(C5:E5) -> 65 | H5: =E5+D5+C5 -> 65
B6: UD Trucks | C6: 16 | D6: 0 | E6: 40 | F6: Level #3 - 40 | G6: =SUM(C6:E6) -> 56 | H6: =E6+D6+C6 -> 56
B7: SAP | C7: 20 | D7: 0 | E7: 36 | F7: Level #4 - 36 | G7: =SUM(C7:E7) -> 56 | H7: =E7+D7+C7 -> 56
B8: Texas Instruments | C8: 0 | D8: 98 | E8: 288 | F8: Level #1 - 36 Level # 2 - 72 Level #3 - 72 Level #4 - 36 Level #7 - 72 | G8: =SUM(C8:E8) -> 386 | H8: =E8+D8+C8 -> 386
B9: Boeing | C9: 0 | D9: 21 | E9: =72+19 -> 91 | F9: Level #1 - 19 Level #5 - 72 | G9: =SUM(C9:E9) -> 112 | H9: =E9+D9+C9 -> 112
B10: Renesas | C10: 12 | D10: 0 | E10: 11 | F10: Level #1 - 11 | G10: =SUM(C10:E10) -> 23 | H10: =E10+D10+C10 -> 23
B11: Bagmane | E11: 6 | F11: Level #1 - 6 | G11: =SUM(C11:E11) -> 6 | H11: =E11+D11+C11 -> 6
B12: Total | C12: =SUM(C5:C10) -> 67 | D12: =SUM(D5:D10) -> 133 | E12: =SUM(E5:E11) -> 504 | G12: =SUM(G5:G11) -> 704 | H12: =SUM(H5:H11) -> 704

Sheet Olympia
A1: Site Detail
A3: Sr No | B3: Site Code | C3: Cluster | D3: Site Address | E3: Country | F3: State | G3: Region | H3: Type of Site | I3: Climatic Zone | J3: Sector | K3: Entity Owner | L3: Percentage
A4: 1 | B4: Olympia | C4: India | D4: M/s Bagmane Developers Pvt. Ltd. Olympia Khata No66-1, Bagmane tech park, CV Raman nagar, Byrasandra village, KR puram | E4: India | F4: Karnataka | G4: South | H4: Multi Tenant | I4: Moderate | J4: Office | K4: Bagmane Developers Private Ltd | L4: 1
A8: Building Name | B8: Building Type | C8: Green Certification | D8: Total Construction Area | E8: Total Saleable Area | F8: Total Landscaping Area | G8: Facade Area | H8: Building Construction Start Date | I8: Building Completion Date | J8: Building Handover Start Date | K8: Building Handover End Date
A9: Olympia | D9: 330333 Sq feet | E9: 324042 sq feet | F9: 27351.06(in sqft) | G9: 87699(in sqft) | H9: NA | I9: 2003 | J9: NA | K9: NA
A13: Floor Area Details
A14: Building Name | B14: Status | C14: Floor | D14: Floor Area (in sqft) | E14: Unit | G14: As per Fire NOC
A15: Office Block | B15: Leased | C15: Ground Floor | D15: 37663.821 | G15: 4054.10 Sq. mtrs.
A16: Office Block | B16: Leased | C16: 1st floor | D16: 37663.82 | G16: 4054.10 Sq. mtrs.
A17: Office Block | B17: Leased | C17: 2nd floor | D17: 50013.433 | G17: 4646.40 Sq. mtrs.
A18: Office Block | B18: Leased | C18: 3rd floor | D18: 39893.09 | G18: 3706.19 Sq. Mtrs.
A19: Office Block | B19: Leased | C19: 4th floor | D19: 40606.52 | G19: 3772.47Sq. Mtrs.
A20: Office Block | B20: Leased | C20: 5th floor | D20: 41320.06 | G20: 3838.76 Sq. Mtrs.
A21: Office Block | B21: Leased | C21: 6th floor | D21: 42447.91 | G21: 3943.54 Sq. Mtrs.
A22: Office Block | B22: Leased | C22: 7th floor | D22: 48197 | G22: 4477.64 Sq. Mtrs
A25: Site Operational Details
A26: Type of connection | B26: No Of HT Meters | C26: No Of LT Meters (KWH) | D26: No Of Ammeters | E26: No Of Voltmeters | F26: Type Of Tarrif | G26: Service Provider | H26: Connected Load (KVA) | I26: Sanction Load(KVA) | J26: Contract Demand (KVA) | K26: Maximum Demand (KVA) | L26: Billing Demand (KVA) | M26: STP-Methodology | N26: STP Capacity (KLD)
A27: HT - Utility Block | B27: 4 | C27: 40 | D27: 34 | E27: 34 | F27: Commercial-1HT2B | G27: BESCOM | H27: 3650 | I27: =3000+1950 -> 4950 | J27: =3000+1950 -> 4950 | K27: =752+892 -> 1644 | L27: =2700+L28 -> 2700 | M27: ASP | N27: 100
A28: HT - Office Block
A30: Air-condition Details
A31: Type of Air-condition | B31: Total HVAC Load (in TR)
A32: Water Cooled Chiller | B32: NA
A33: Air Cooled Chiller (3 Nos.) | B33: =205*3 -> 615
A36: Water Source Details
A37: Type of Water Source | B37: Water Input (in KLD)
A38: Tanker | B38: NA
A39: Borewell | B39: 1057KL | C39: 80
A40: STP | B40: 1350KL | C40: 70
A42: Water Tank Details
A43: Type of Water Tank | B43: Location of Tank | C43: Tank Capacity(in KL) | D43: Size of Tank(in cu.ft.)
A44: Fire Water tank-1 | B44: Terrace OHT | C44: 19 | D44: =C44*35.3146 -> 670.9774
A45: Fire Water tank-2 Sump | B45: Ground | C45: 150 | D45: =C45*35.3146 -> 5297.19
A46: Raw Water tank | B46: Ground | C46: 100 | D46: =C46*35.3146 -> 3531.46
A47: Treated Water tank | B47: Ground | C47: 100 | D47: =C47*35.3146 -> 3531.46
A48: Rain Water tank - 1 | B48: Ground | C48: 600 | D48: =C48*35.3146 -> 21188.76
A49: STP Flushing tank | B49: Terrace | C49: 64 | D49: =C49*35.3146 -> 2260.1344
A50: Domestic tank | B50: Terrace | C50: 31 | D50: =C50*35.3146 -> 1094.7526
A51: Chiller makeup tank | B51: Terrace | C51: 1 | D51: =C51*35.3146 -> 35.3146
A52: Fire sump | B52: MLCP Ground floor | C52: 250 | D52: =C52*35.3146 -> 8828.65
A53: MLCP Ground floor OHT | B53: MLCP Terrace | C53: 35 | D53: =C53*35.3146 -> 1236.011
...

Sheet Commerz-1
A1: Site Detail
A3: Sr No | B3: Site Code | C3: Cluster | D3: Site Address | E3: Country | F3: State | G3: Region | H3: Type of Site | I3: Climatic Zone | J3: Sector | K3: Entity Owner | L3: Percentage
A4: 1 | B4: Commerz | C4: India | D4: M/s Bagmane Developers Pvt Ltd 66/1-3, Commerz - I Building (Retail - I), Bagmane Tech Park, CV Raman Nagar, Bengaluru-560093 | E4: India | F4: Karnataka | G4: South | H4: Multi Tenant | I4: Moderate | J4: Office | K4: Bagmane Developers Private Limited | L4: 1
A8: Building Name | B8: Building Type | C8: Green Certification | D8: Total Construction Area | E8: Total Saleable Area | F8: Total Landscaping Area | G8: Facade Area | H8: Building Construction Start Date | I8: Building Completion Date | J8: Building Handover Start Date | K8: Building Handover End Date
A9: Commerz-1 | C9: LEED-Gold | D9: 21252.95 Sq. mtrs. | E9: 228764.7 | F9: 510.02 sqft | G9: 70662 sqft | H9: 2004 | I9: 2006 | J9: 2006 | K9: 2006
D10: =10.764*21252.95 -> 228766.75
A13: Floor Area Details
A14: Building Name | B14: Status | C14: Floor | D14: Floor Area (in sqft) | E14: Unit | G14: As per Fire NOC
A15: Commerz-1 | B15: Leased | C15: Ground Floor | D15: 25111.23 | G15: 2332.91 Sq. mtrs.
A16: Commerz-1 | B16: Leased | C16: 1st floor | D16: 26498.37 | G16: 2461.78 Sq. mtrs.
A17: Commerz-1 | B17: Leased | C17: 2nd floor | D17: 25111.23 | G17: 2332.91 Sq. mtrs.
A18: Commerz-1 | B18: Leased | C18: 3rd floor | D18: 25793.23 | G18: 2396.27 Sq. mtrs.
A19: Commerz-1 | B19: Leased | C19: 4th floor | D19: 24455 | G19: 2271.95 Sq. mtrs.
A20: Commerz-1 | B20: Leased | C20: 5th floor | D20: 23919.34 | G20: 2222.18 Sq. Mtrs.
A21: Commerz-1 | B21: Leased | C21: 6th floor | D21: 21538 | G21: 2000.95 Sq. Mtrs.
A22: Commerz-1 | B22: Leased | C22: Upper Basement | D22: 28169.15 | G22: 2617 Sq. Mtrs.
A23: Commerz-1 | B23: Leased | C23: Lower Basement | D23: 28169.15 | G23: 2617 Sq. Mtrs.
A24: Site Operational Details
A25: Type of connection | B25: No Of HT Meters | C25: No Of LT Meters (KWH) | D25: No Of Ammeters | E25: No Of Voltmeters | F25: Type Of Tarrif | G25: Service Provider | H25: Connected Load (KVA) | I25: Sanction Load(KVA) | J25: Contract Demand (KVA) | K25: Maximum Demand (KVA) | L25: Billing Demand (KVA) | M25: STP-Methodology | N25: STP Capacity (KLD)
A26: HT - Commerz-1 | B26: 2 | C26: 165 | D26: 57 | E26: 51 | F26: Commercial-HT2B | G26: BESCOM | H26: 3600 | I26: 3600 | J26: 3600 | K26: 700 | L26: 3240 | M26: MBR | N26: 150
A27: HT - Commerz-1 | B27: 2 | F27: Commercial-HT2B | G27: BESCOM | H27: 400 | I27: 400 | J27: 400 | K27: 416 | L27: 360
H28: =SUM(H26:H27) -> 4000 | I28: =SUM(I26:I27) -> 4000 | J28: =SUM(J26:J27) -> 4000 | K28: =SUM(K26:K27) -> 1116 | L28: =SUM(L26:L27) -> 3600
A29: Air-condition Details
A30: Type of Air-condition | B30: Total HVAC Load (in TR)
A31: Water Cooled Chiller (2 Nos.) | B31: NA
A32: Air Cooled Chiller (6 Nos.) | B32: =150*6 -> 900
A35: Water Source Details (Monthly)
A36: Type of Water Source | B36: Water Input (in KLD)
A37: Tanker | B37: NA
A38: Borewell | B38: 60
A39: STP | B39: 50
A41: Water Tank Details
A42: Type of Water Tank | B42: Location of Tank | C42: Tank Capacity(in KL) | D42: Size of Tank(in cu.ft.)
A43: Fire Water tank-1 | B43: Lower Basement | C43: 200 | D43: =C43*35.3146 -> 7062.92
A44: Raw Water tank | B44: Lower Basement | C44: 75 | D44: =C44*35.3146 -> 2648.595
A45: Treated Water tank | B45: Lower Basement | C45: 75 | D45: =C45*35.3146 -> 2648.595
A46: Fire Water tank-1 | B46: Terrace | C46: 40 | D46: =C46*35.3146 -> 1412.584
A47: Domestic Treated Water tank - 1 | B47: Terrace | C47: 20 | D47: =C47*35.3146 -> 706.292
A48: Makeup tank - Flushing | B48: Terrace | C48: 10 | D48: =C48*35.3146 -> 353.146
A49: STP Raw (Equalisation Water Tank-1 | B49: Lower Basement | C49: 52 | D49: =C49*35.3146 -> 1836.3592
...

Sheet Commerz 1 Parking Details
F1: Area (Sft) | J1: Parking Details
B2: Building Name | D2: Client Name | E2: Floor | F2: Carpet Area(in sqft) | G2: Leased Area(in sqft) | H2: Super Built-up Area (in sqft) | J2: Parking Floor | K2: No. of parkings as per Plan | L2: No. of parkings as on Actuals | M2: No. of Stack Parking | N2: No. of Open Parking | O2: No. of Covered Parking | P2: No. of Visitors Parking | Q2: No. of Reserved Parking | R2: No. of 2W Parking | S2: No. of 4W Parking
B3: Commerz 1 | D3: Retail | E3: GF | G3: 25111 | H3: 25111 | K3: NA | L3: NA | M3: NA | N3: NA | O3: NA | P3: NA | Q3: NA | R3: NA | S3: NA
B4: Commerz 1 | D4: HDFC Bank | E4: GF | K4: NA | L4: NA | M4: NA | N4: NA | O4: NA | P4: NA | Q4: NA | R4: NA | S4: NA
B5: Commerz 1 | D5: State Bank Of India | E5: 1st | G5: 1802 | H5: 1802 | J5: Upper Basement | K5: 4 | L5: 4 | M5: 0 | N5: 0 | O5: 4 | P5: 0 | Q5: 0 | R5: 0 | S5: 4
B6: Commerz 1 | D6: Union Bank of Inida | E6: 1st | G6: 1425 | H6: 1425 | J6: Upper Basement | K6: 1 | L6: 1 | M6: 0 | N6: 0 | O6: 1 | P6: 0 | Q6: 0 | R6: 0 | S6: 1
B7: Commerz 1 | D7: Informatica | E7: 1st | G7: 25096 | H7: 25096 | J7: Lower basement | K7: 10 | L7: 10 | M7: 0 | N7: 0 | O7: 10 | P7: 0 | Q7: 0 | R7: 0 | S7: 10
B8: Commerz 1 | D8: Vialto | E8: 2nd | G8: 32735 | H8: 32735 | J8: Upper Basement | K8: 19 | L8: 19 | M8: 0 | N8: 0 | O8: 19 | P8: 0 | Q8: 0 | R8: 0 | S8: 19
B9: Commerz 1 | D9: - | E9: 3rd | G9: 30122 | H9: 30122 | J9: Upper Basement & Ground floor | K9: 31 & 7 | L9: 31 & 7 | M9: 0 | N9: 7 | O9: 31 | P9: 0 | Q9: 0 | R9: 0 | S9: 38
B10: Commerz 1 | D10: Cisco | E10: 4th | G10: 30122 | H10: 30122 | J10: Upper Basement | K10: 38 | L10: 38 | M10: 0 | N10: 0 | O10: 38 | P10: 0 | Q10: 0 | R10: 0 | S10: 38
B11: Commerz 1 | D11: Informatica | E11: 5th | G11: 29623 | H11: 29623 | J11: Upper Basement & Ground floor | K11: 87+5 | L11: 87+5 | M11: 0 | N11: 5 | O11: 87 | P11: 0 | Q11: 0 | R11: 0 | S11: 92
B12: Commerz 1 | D12: Informatica | E12: 6th | G12: 29623 | H12: 29623
J15: MLCP Parking
I16: Client Name | J16: Parking Floor | K16: No. of parkings as per Plan | L16: No. of parkings as on Actuals | M16: No. of Stack Parking | N16: No. of Open Parking | O16: No. of Covered Parking | P16: No. of Visitors Parking | Q16: No. of Reserved Parking | R16: No. of 2W Parking | S16: No. of 4W Parking
J17: Level 1
J18: Level 2
J19: Level 3
J20: Level 4
J21: Level 5
J22: Level 6
J23: Level 7
J24: Level 8

Sheet Commerz-2
A1: Site Detail
A3: Sr No | B3: Site Code | C3: Cluster | D3: Site Address | E3: Country | F3: State | G3: Region | H3: Type of Site | I3: Climatic Zone | J3: Sector | K3: Entity Owner | L3: Percentage
A4: 1 | B4: Commerz 2 | C4: India | D4: M/s Bgmane Developers Pvt Ltd 66/1-3 - Commerz 2, Commerz Bagmane Tech park Byrasandra CV Raman Nagar-560093 | E4: India | F4: Karnataka | G4: South | H4: Single Tenant | I4: Moderate | J4: Office | K4: Bagmane Developers Private Limited | L4: 1
A8: Building Name | B8: Building Type | C8: Green Certification | D8: Total Construction Area | E8: Total Saleable Area | F8: Total Landscaping Area | G8: Facade Area | H8: Building Construction Start Date | I8: Building Completion Date | J8: Building Handover Start Date | K8: Building Handover End Date
A9: Commerz-2 | C9: LEED-Platinum | D9: 220326.48 Sq. mtrs. | E9: 220617 | F9: 3463.97 sqft | G9: 40878 sqft | H9: 2008 | I9: 2010 | J9: 2010 | K9: 2010
D10: =10.764*220326.48 -> 2371594.2
A13: Floor Area Details
A14: Building Name | B14: Status | C14: Floor | D14: Floor Area (in sqft) | E14: Unit | G14: As per Fire NOC
A15: Commerz-2 | B15: Leased (MLCP) | C15: Ground Floor | D15: 13637.87 | G15: 1267 Sq. mtrs.
A16: Commerz-2 | B16: Leased (MLCP) | C16: 1st floor | D16: 13853.15 | G16: 1287 Sq. mtrs.
A17: Commerz-2 | B17: Leased (MLCP) | C17: 2nd floor | D17: 13853.15 | G17: 1287 Sq. mtrs.
A18: Commerz-2 | B18: Leased (MLCP) | C18: 3rd floor | D18: 25887.2 | G18: 2405 Sq. mtrs.
A19: Commerz-2 | B19: Leased (MLCP) | C19: 4th floor | D19: 25887.2 | G19: 2405 Sq. mtrs.
A20: Commerz-2 | B20: Leased (office floor) | C20: 5th floor | D20: 25499.7 | G20: 2369 Sq. mtrs
A21: Commerz-2 | B21: Leased (office floor) | C21: 6th floor | D21: 25499.7 | G21: 2369 Sq. mtrs
A22: Commerz-2 | B22: Leased (office floor) | C22: 7th floor | D22: 25499.7 | G22: 2369 Sq. mtrs
A23: Commerz-2 | B23: Leased (office floor) | C23: 8th floor | D23: 25499.7 | G23: 2369 Sq. mtrs
A24: Commerz-2 | B24: Leased (office floor) | C24: 9th floor | D24: 25499.7 | G24: 2369 Sq. mtrs
A26: Site Operational Details
A27: Type of connection | B27: No Of HT Meters | C27: No Of LT Meters (KWH) | D27: No Of Ammeters | E27: No Of Voltmeters | F27: Type Of Tarrif | G27: Service Provider | H27: Connected Load (KVA) | I27: Sanction Load(KVA) | J27: Contract Demand (KVA) | K27: Maximum Demand (KVA) | L27: Billing Demand (KVA) | M27: STP-Methodology | N27: STP Capacity (KLD)
A28: HT - Commerz-2 | B28: 2 | C28: 66 | D28: 17 | E28: 13 | F28: Industrial-HT2A | G28: BESCOM | H28: 1650 | I28: 1650 | J28: 1650 | L28: 1485 | M28: SBR | N28: 150
A31: Air-condition Details
A32: Type of Air-condition | B32: Total HVAC Load (in TR)
A33: Water Cooled Chiller (2 Nos.) | B33: NA
A34: Air Cooled Chiller (2 Nos.) | B34: =250*2 -> 500
A37: Water Source Details
A38: Type of Water Source | B38: Water Input (in KLD)
A39: Tanker | B39: NA
A40: Borewell | B40: 20
A41: STP | B41: 25
A43: Water Tank Details
A44: Type of Water Tank | B44: Location of Tank | C44: Tank Capacity(in KL) | D44: Size of Tank(in cu.ft.)
A45: Fire Water tank-1 | B45: Ground Floor | C45: 250 | D45: =C45*35.3146 -> 8828.65
A46: Raw Water tank | B46: Ground Floor | C46: 75 | D46: =C46*35.3146 -> 2648.595
A47: Fire Water tank-1 | B47: Terrace | C47: 40 | D47: =C47*35.3146 -> 1412.584
A48: Domestic Treated Water tank - 1 | B48: Terrace | C48: 20 | D48: =C48*35.3146 -> 706.292
A49: Makeup tank - Flushing | B49: Terrace | C49: 10 | D49: =C49*35.3146 -> 353.146
A50: STP Raw Water Tank | B50: Ground Floor | C50: 67.8 | D50: =C50*35.3146 -> 2394.3299
A51: STP Aeration Tank-1 | B51: Ground Floor | C51: 63.3 | D51: =C51*35.3146 -> 2235.4142
A52: STP Aeration Tank-2 | B52: Ground Floor | C52: 63.3 | D52: =C52*35.3146 -> 2235.4142
...

Sheet Commerz 2 Parking Details
F1: Area (Sft) | J1: Parking Details
B2: Building Name | D2: Client Name | E2: Floor | F2: Carpet Area(in sqft) | G2: Leased Area(in sqft) | H2: Super Built-up Area (in sqft) | J2: Parking Floor | K2: No. of parkings as per Plan | L2: No. of parkings as on Actuals | M2: No. of Stack Parking | N2: No. of Open Parking | O2: No. of Covered Parking | P2: No. of Visitors Parking | Q2: No. of Reserved Parking | R2: No. of 2W Parking | S2: No. of 4W Parking
B3: Commerz 2 | D3: Informatica | E3: GF (MLCP) | G3: 13637.87 | H3: 13637.87
B4: Commerz 2 | D4: Informatica | E4: 1st (MLCP) | G4: 13853.15 | H4: 13853.15
B5: Commerz 2 | D5: Informatica | E5: 2nd (MLCP) | G5: 13853.15 | H5: 13853.15
B6: Commerz 2 | D6: Informatica | E6: 3rd (MLCP) | G6: 25887 | H6: 25887
B7: Commerz 2 | D7: Informatica | E7: 4th (MLCP) | G7: 25887 | H7: 25887
B8: Commerz 2 | D8: Informatica | E8: 5th | G8: 29986 | H8: 29986
B9: Commerz 2 | D9: Informatica | E9: 6th | G9: 29986 | H9: 29986
B10: Commerz 2 | D10: Informatica | E10: 7th | G10: 29986 | H10: 29986
B11: Commerz 2 | D11: Informatica | E11: 8th | G11: 29986 | H11: 29986
B12: Commerz 2 | D12: Informatica | E12: 9th | G12: 29986 | H12: 29986
J15: MLCP Parking
I16: Client Name | J16: Parking Floor | K16: No. of parkings as per Plan | L16: No. of parkings as on Actuals | M16: No. of Stack Parking | N16: No. of Open Parking | O16: No. of Covered Parking | P16: No. of Visitors Parking | Q16: No. of Reserved Parking | R16: No. of 2W Parking | S16: No. of 4W Parking
I17: Informatica | J17: GF | K17: 19 | L17: 19 | M17: 0 | N17: 0 | O17: 19 | P17: 0 | Q17: 0 | R17: 0 | S17: 0
J18: 1F | K18: 27 | L18: 27 | M18: 0 | N18: 0 | O18: 27 | P18: 0 | Q18: 0 | R18: 0 | S18: 0
J19: 2F | K19: 29 | L19: 29 | M19: 0 | N19: 0 | O19: 29 | P19: 0 | Q19: 0 | R19: 0 | S19: 0
J20: 3F | K20: 84 | L20: 84 | M20: 0 | N20: 0 | O20: 84 | P20: 0 | Q20: 0 | R20: 0 | S20: 0
J21: 4F | K21: 28 | L21: 28 | M21: 0 | N21: 0 | O21: 28 | P21: 0 | Q21: 0 | R21: 0 | S21: 0
